Workbook

Sheet README
A1: ROW Module – Consolidated Feature Union
A3: Primary focus | B3: The 'ROW Features' sheet is the deliverable: features for Right-of-Way (ROW) land acquisition, relocation, condemnation, payments, property management, utilities coordination, and the platform capabilities ROW needs (documents, workflow, GIS, reporting, security, integration). It is built only from the six ROW/real-estate requirement documents (NH DOT, Idaho, NMDOT, WSDOT, Austin, Osceola §6.1.7).
A4: City / County sheet | B4: 'City-County ROW Use' is a SEPARATE sheet. It holds requirements for managing USE of public right-of-way (permits, inspections, street/curb data) from city/county-level documents (Detroit, Calgary, Regina, Smart ROW matrix). These are city/county level requirements and are NOT part of the ROW module scope above; they are kept only for reference.
A5: Sheets | B5: ROW Features – the union for the ROW module. City-County ROW Use – separate, reference only. Traceability – every source item behind every feature (verbatim). Sources – the documents and how priority was read. Summary – formula counts. Open Questions – items I could not determine.
A6: Consolidated priority (formula) | B6: Computed from the per-source codes, using the HIGHEST rating any counted source gave: Must Have (M) > Should Have (S) > Could Have (C) > Stated – no priority (E) > Aurigo-only. It means 'at least one source requires it', not agreement – use '# sources', '# sources rating Must' and 'Consensus tier' for weight.
A7: Per-source codes | B7: M = Must/Required. S = Should/Desired/Medium/Preferred. C = Could/Optional/Low. E = stated as needed but no priority given (typical of RFIs). Blank = not mentioned. Exact rule per source is on the Sources sheet; the source's own label is kept in 'Source references'.
A8: Consensus tier | B8: Tier 1 = rated Must by 3+ sources; Tier 2 = Must in 2; Tier 3 = Must in 1; Tier 4 = Should only; Tier 5 = Could only; Tier 6 = stated, no priority. Useful because NH and Idaho rate almost everything as required.
A9: Aurigo coverage columns | B9: Judged ONLY from Aurigo documents in the project (ROW Pro SOW – Original and Pro versions, demo script, deck, library list). 'Covered (SOW)' = named in the SOW; 'Partial' = related but not the full ask; 'Platform / demo only' = in demo script/deck, not SOW; 'Not evidenced' = nothing found in those documents (not the same as 'product lacks it').
A10: 'Also asked by city/county docs' | B10: On ROW Features, this column notes where a city/county document also asks for a similar capability. Those mentions are NOT counted in priority or source counts.
A11: De-duplication caveat | B11: Feature count is my consolidation, not a count of source requirements. Similar asks were merged; report-tool minutiae in the Idaho RFP are summarised in a few features. NH rows with truncated text are not mapped (see Open Questions).
A12: No-guess policy | B12: Descriptions restate what sources say. Undefined terms are quoted, not interpreted; see Notes and Open Questions.
A13: Build roadmap columns | B13: 'ROW Features' columns Z-AC: Release (R01-R35), Release theme, Build sequence (unique 1-323), Depends on. See the 'Release Key' sheet for release themes, rules and assumptions.
A14: New requirements (ROW-233 to ROW-323) | B14: 91 process-step requirements added from New_Requirements.md (rows 236-326 of 'ROW Features'). They come from process sources (SOPs, DOT manual sections, lifecycle stages), not from the six RFP/RFI documents, so columns M-R are blank, priority is 'Stated – no priority', consensus tier is Tier 6, and Aurigo coverage is 'Not assessed (new)'. Evidence is in 'Source references' and on the Traceability sheet (rows marked source code NEW).

Sheet Release Key
A1: ROW BUILD ROADMAP – RELEASE KEY
A2: Release and Build sequence are on the 'ROW Features' sheet (columns Z-AC). They are judgment assignments, not formulas. Each release is a thin, usable slice; sequence is unique (1-323).
A4: Release | B4: Theme | C4: # features | D4: First seq | E4: Last seq | F4: Release in version 2 file | G4: Why it sits here (basis)
A5: R01 | B5: Platform foundation & UI standards | C5: =COUNTIF('ROW Features'!$Z$4:$Z$326,A5) -> 13 | D5: =_xlfn.MINIFS('ROW Features'!$AB$4:$AB$326,'ROW Features'!$Z$4:$Z$326,A5) -> 1 | E5: =_xlfn.MAXIFS('ROW Features'!$AB$4:$AB$326,'ROW Features'!$Z$4:$Z$326,A5) -> 13 | F5: R01 | G5: Everything else is built on hosting, environments, the shared data model, role/field security, audit and the UI standards (accessibility, browsers, usability) that every later form must follow.
A6: R02 | B6: Project & parcel core | C6: =COUNTIF('ROW Features'!$Z$4:$Z$326,A6) -> 11 | D6: =_xlfn.MINIFS('ROW Features'!$AB$4:$AB$326,'ROW Features'!$Z$4:$Z$326,A6) -> 14 | E6: =_xlfn.MAXIFS('ROW Features'!$AB$4:$AB$326,'ROW Features'!$Z$4:$Z$326,A6) -> 24 | F6: R02 | G6: First business slice: a ROW project and its parcels (System Design 3a: Project and Parcel Management comes first), plus the document repository, workflow engine and tasks every later module uses. Parent-tract and tax-parcel link (ROW-233) attaches to the parcel record.
A7: R03 | B7: Owners, stakeholders & parcel team | C7: =COUNTIF('ROW Features'!$Z$4:$Z$326,A7) -> 9 | D7: =_xlfn.MINIFS('ROW Features'!$AB$4:$AB$326,'ROW Features'!$Z$4:$Z$326,A7) -> 25 | E7: =_xlfn.MAXIFS('ROW Features'!$AB$4:$AB$326,'ROW Features'!$Z$4:$Z$326,A7) -> 33 | F7: R03 | G7: Owners, interests, contacts and team roles hang off the parcel (System Design: M1 -> M2). Demographics and tax data are captured here so payments and Title VI reporting have the data later.
A8: R04 | B8: Project funding, parcel depth, acquisition plan & map viewer | C8: =COUNTIF('ROW Features'!$Z$4:$Z$326,A8) -> 12 | D8: =_xlfn.MINIFS('ROW Features'!$AB$4:$AB$326,'ROW Features'!$Z$4:$Z$326,A8) -> 34 | E8: =_xlfn.MAXIFS('ROW Features'!$AB$4:$AB$326,'ROW Features'!$Z$4:$Z$326,A8) -> 45 | F8: R04 | G8: Deepens the parcel and project records (funding, estimates, budgets, acquisition plan, interests by type, grouping, split/combine, batch updates) and adds the map viewer that appraisal, utilities and inventory reuse.
A9: R05 | B9: Templates, correspondence & e-signature | C9: =COUNTIF('ROW Features'!$Z$4:$Z$326,A9) -> 4 | D9: =_xlfn.MINIFS('ROW Features'!$AB$4:$AB$326,'ROW Features'!$Z$4:$Z$326,A9) -> 46 | E9: =_xlfn.MAXIFS('ROW Features'!$AB$4:$AB$326,'ROW Features'!$Z$4:$Z$326,A9) -> 49 | F9: R05 | G9: Templates, mail merge and e-signature are needed by hearing notices and title reports (R07), notices to owners (R06), offers (R11) and relocation notices (R18), so they come first.
A10: R06 | B10: Acquisition rules, authorization, compliance & alerts | C10: =COUNTIF('ROW Features'!$Z$4:$Z$326,A10) -> 16 | D10: =_xlfn.MINIFS('ROW Features'!$AB$4:$AB$326,'ROW Features'!$Z$4:$Z$326,A10) -> 50 | E10: =_xlfn.MAXIFS('ROW Features'!$AB$4:$AB$326,'ROW Features'!$Z$4:$Z$326,A10) -> 65 | F10: R06 | G10: System Design: the Acquisition Process and Compliance Engine governs Acquisition and Negotiation. ROW authorization, site visit, Notice to Owner and the plan-review gate belong to the pre-acquisition steps in Diagram 1. Alerts are built here because deadline and next-action reminders depend on them.
A11: R07 | B11: Title & abstraction | C11: =COUNTIF('ROW Features'!$Z$4:$Z$326,A11) -> 15 | D11: =_xlfn.MINIFS('ROW Features'!$AB$4:$AB$326,'ROW Features'!$Z$4:$Z$326,A11) -> 66 | E11: =_xlfn.MAXIFS('ROW Features'!$AB$4:$AB$326,'ROW Features'!$Z$4:$Z$326,A11) -> 80 | F11: R07 | G11: Title and survey both feed appraisal (System Design: M3 and M4 -> M5). Title ordering is built before title research. Uses document versioning, role-based confidential access (R01) and mail merge (R05).
A12: R08 | B12: Survey, plans & appraisal package | C12: =COUNTIF('ROW Features'!$Z$4:$Z$326,A12) -> 9 | D12: =_xlfn.MINIFS('ROW Features'!$AB$4:$AB$326,'ROW Features'!$Z$4:$Z$326,A12) -> 81 | E12: =_xlfn.MAXIFS('ROW Features'!$AB$4:$AB$326,'ROW Features'!$Z$4:$Z$326,A12) -> 89 | F12: R08 | G12: Survey data and CAD files feed appraisal (System Design: M4 -> M5). GIS quality check, legal/sketch review and appraisal package assembly close out Diagram 2 and hand the parcel to appraisal.
A13: R09 | B13: Appraisal core | Utilities core (parallel track) | C13: =COUNTIF('ROW Features'!$Z$4:$Z$326,A13) -> 20 | D13: =_xlfn.MINIFS('ROW Features'!$AB$4:$AB$326,'ROW Features'!$Z$4:$Z$326,A13) -> 90 | E13: =_xlfn.MAXIFS('ROW Features'!$AB$4:$AB$326,'ROW Features'!$Z$4:$Z$326,A13) -> 109 | F13: R09 | G13: Appraisal intake needs the assembled package (R08). Utilities run in parallel with acquisition per your direction; the utilities core needs only project, parcel, tasks and documents.
A14: R10 | B14: Appraisal depth | Utilities agreements & reimbursement (parallel track) | C14: =COUNTIF('ROW Features'!$Z$4:$Z$326,A14) -> 20 | D14: =_xlfn.MINIFS('ROW Features'!$AB$4:$AB$326,'ROW Features'!$Z$4:$Z$326,A14) -> 110 | E14: =_xlfn.MAXIFS('ROW Features'!$AB$4:$AB$326,'ROW Features'!$Z$4:$Z$326,A14) -> 129 | F14: R10 | G14: Appraiser management, report writing, specialty reports and comparable-sales data build on the appraisal core and the R04 map viewer. On the utilities track: prior rights, cost authorization, relocation notices, estimate review, Buy America and milestones build on the utilities core and its agreements.
A15: R11 | B15: Pre-offer review, offers & negotiation | C15: =COUNTIF('ROW Features'!$Z$4:$Z$326,A15) -> 13 | D15: =_xlfn.MINIFS('ROW Features'!$AB$4:$AB$326,'ROW Features'!$Z$4:$Z$326,A15) -> 130 | E15: =_xlfn.MAXIFS('ROW Features'!$AB$4:$AB$326,'ROW Features'!$Z$4:$Z$326,A15) -> 142 | F15: R11 | G15: Offers start only after just compensation is approved (R09). Management review, funding check and approval thresholds come before the first offer. Impasse data created here feeds condemnation (R21).
A16: R12 | B16: Agreements, easements & alternative acquisition paths | C16: =COUNTIF('ROW Features'!$Z$4:$Z$326,A16) -> 9 | D16: =_xlfn.MINIFS('ROW Features'!$AB$4:$AB$326,'ROW Features'!$Z$4:$Z$326,A16) -> 143 | E16: =_xlfn.MAXIFS('ROW Features'!$AB$4:$AB$326,'ROW Features'!$Z$4:$Z$326,A16) -> 151 | F16: R12 | G16: Agreement approval, subordination letters, easements, key turnover and environmental site assessments follow the settlement (R11). Donation, developer-conveyance and early-acquisition paths reuse the configurable acquisition workflow (ROW-071).
... A39: R35 | B39: Rail & transit (NH-specific) | C39: =COUNTIF('ROW Features'!$Z$4:$Z$326,A39) -> 5 | D39: =_xlfn.MINIFS('ROW Features'!$AB$4:$AB$326,'ROW Features'!$Z$4:$Z$326,A39) -> 319 | E39: =_xlfn.MAXIFS('ROW Features'!$AB$4:$AB$326,'ROW Features'!$Z$4:$Z$326,A39) -> 323 | F39: R28 | G39: Per your direction, NH-specific rail items go last. NH has not defined several of its named systems (see Open Questions #5-6).
B40: Total | C40: =SUM(C5:C39) -> 323
A42: Rules applied
A43: 1. Dependency first: a feature is never built before something it needs. Every 'Depends on' ID has a lower build sequence than the feature itself.
A44: 2. Within the same dependency level, existing features are ordered by Consensus tier (sources rating Must, then number of sources). The 91 new features (ROW-233 to ROW-323) have no tier, so they follow existing features at the same level and are then ordered by ID.
A45: 3. Nothing is treated as already built: Aurigo coverage columns were NOT used for ordering (your direction: fresh start, existing items are to-do).
A46: 4. Thin slices: each release is a coherent set a user group can use. Process order follows the System Design arrows and the numbered process diagrams (project/parcel -> owners/title/survey -> appraisal -> acquisition -> payments -> relocation / condemnation -> clearance -> certification; property management after acquisition).
A47: 5. Parallel tracks (your direction): Utilities run alongside appraisal and payments (R09, R10, R14); web inspection and mobile/field access are delivered together (R27).
A48: 6. Last (your direction): external portals (R32), integrations (R33-R34) and NH-specific rail items (R35). Payments are tracked in-system first (R13); finance integration is R33.
A49: 7. Overlapping features are delivered in the same release, not merged or flagged: ROW-111 and ROW-211 (R33); ROW-058, ROW-107, ROW-108 and ROW-243 (R13); ROW-083 and ROW-292 (R26); ROW-140 and ROW-301 (R29); ROW-139 and ROW-296 (R28).
A50: 8. Not used for ordering (your direction): deadlines and security-certification gating. Certifications (ROW-217) sit in R30.
A52: Assumptions to confirm
A53: A. First customer go-live candidate = after R17 (standard acquisition from project through closing and parcel closure, with data migration and production readiness). Relocation, condemnation, clearance, certification and property management follow. You did not specify a go-live point; move it if needed.
A54: B. System Design shows title and survey feeding appraisal, so appraisal (R09) comes after R07-R08 even though that delays the first end-to-end slice.
... A59: G. Release numbers changed from version 2 because new features needed new slices. Column F shows the version 2 release for each current release.

Sheet ROW Features
A1: ROW MODULE FEATURES – built from ROW / real-estate documents only. City/county permitting & street-data requirements are on the separate 'City-County ROW Use' sheet.
A3: Feature ID | B3: Domain | C3: Category | D3: Sub-category | E3: Feature | F3: Description (plain English) | G3: Requirement type | H3: Consolidated priority | I3: # sources | J3: # sources rating Must | K3: Breadth | L3: Consensus tier | M3: NH | N3: ID | O3: NM | P3: WA | Q3: ATX | R3: OSC | S3: Source references (document – location [source's own priority label]) | T3: Regulation / standard cited | U3: Named systems / tools | V3: Aurigo ROW Pro coverage (provided docs only) | W3: Aurigo evidence | X3: Notes / open questions | Y3: Also asked by city/county docs (not counted) | Z3: Release | AA3: Release theme | AB3: Build sequence (1 = build first) | AC3: Depends on (feature IDs built earlier)
A4: ROW-001 | B4: Land Acquisition & Relocation | C4: Project & Parcel Setup | D4: Project record | E4: ROW project set-up with unique project ID | F4: Create a ROW project record with a unique project number and descriptive data (location, description, project/parcel information). The Aurigo demo script notes the number can be auto-generated or pulled from another system. | G4: Functional | H4: =IF(COUNTIF(M4:R4,"M")>0,"Must Have",IF(COUNTIF(M4:R4,"S")>0,"Should Have",IF(COUNTIF(M4:R4,"C")>0,"Could Have",IF(COUNTA(M4:R4)>0,"Stated – no priority","Aurigo-only (no RFP source)")))) -> Must Have | I4: =COUNTA(M4:R4) -> 2 | J4: =COUNTIF(M4:R4,"M") -> 1 | K4: =IF(I4=0,"Aurigo-only",IF(I4=1,"Single source",IF(I4=2,"Two sources",IF(I4<=4,"Common (3-4)","Broad (5+)")))) -> Two sources | L4: =IF(J4>=3,"Tier 1: Must in 3+ sources",IF(J4=2,"Tier 2: Must in 2 sources",IF(J4=1,"Tier 3: Must in 1 source",IF(COUNTIF(M4:R4,"S")>0,"Tier 4: Should only",IF(COUNTIF(M4:R4,"C")>0,"Tier 5: Could only",IF(I4>0,"Tier 6: stated, no priority","Aurigo-only")))))) -> Tier 3: Must in 1 source | N4: M | P4: E | S4: Idaho ITD RFP Event 85 – ROWMS: §9 Scope of Work ['must' requirement (§9)] WSDOT RFI (2023): Perf. Requirements – Baseline System Capabilities [RFI – performance requirement list (no priority given)] | V4: Covered (SOW) | W4: Pro SOW: 'Project/Land Entity', 'Project Location'; Demo: ROW Project Details form | Z4: R02 | AA4: Project & parcel core | AB4: 14 | AC4: ROW-084, ROW-212
A5: ROW-002 | B5: Land Acquisition & Relocation | C5: Project & Parcel Setup | D5: Project record | E5: Configurable multi-level Work Breakdown Structure (WBS) | F5: Break a project into configurable levels (example in the source: project, phase, task, activity, sub-activity, line item, category, parcel, sub-parcel, county, city). | G5: Functional | H5: =IF(COUNTIF(M5:R5,"M")>0,"Must Have",IF(COUNTIF(M5:R5,"S")>0,"Should Have",IF(COUNTIF(M5:R5,"C")>0,"Could Have",IF(COUNTA(M5:R5)>0,"Stated – no priority","Aurigo-only (no RFP source)")))) -> Must Have | I5: =COUNTA(M5:R5) -> 1 | J5: =COUNTIF(M5:R5,"M") -> 1 | K5: =IF(I5=0,"Aurigo-only",IF(I5=1,"Single source",IF(I5=2,"Two sources",IF(I5<=4,"Common (3-4)","Broad (5+)")))) -> Single source | L5: =IF(J5>=3,"Tier 1: Must in 3+ sources",IF(J5=2,"Tier 2: Must in 2 sources",IF(J5=1,"Tier 3: Must in 1 source",IF(COUNTIF(M5:R5,"S")>0,"Tier 4: Should only",IF(COUNTIF(M5:R5,"C")>0,"Tier 5: Could only",IF(I5>0,"Tier 6: stated, no priority","Aurigo-only")))))) -> Tier 3: Must in 1 source | N5: M | S5: Idaho ITD RFP Event 85 – ROWMS: §9 Scope of Work ['must' requirement (§9)] | V5: Not evidenced | W5: No matching item found in the provided Aurigo documents (SOW, demo script, deck, library list). | Z5: R02 | AA5: Project & parcel core | AB5: 17 | AC5: ROW-001
A6: ROW-003 | B6: Land Acquisition & Relocation | C6: Project & Parcel Setup | D6: Project record | E6: Project tracking by region / district | F6: Track projects by the agency's regions or districts and filter/report by region or district. | G6: Functional | H6: =IF(COUNTIF(M6:R6,"M")>0,"Must Have",IF(COUNTIF(M6:R6,"S")>0,"Should Have",IF(COUNTIF(M6:R6,"C")>0,"Could Have",IF(COUNTA(M6:R6)>0,"Stated – no priority","Aurigo-only (no RFP source)")))) -> Must Have | I6: =COUNTA(M6:R6) -> 3 | J6: =COUNTIF(M6:R6,"M") -> 2 | K6: =IF(I6=0,"Aurigo-only",IF(I6=1,"Single source",IF(I6=2,"Two sources",IF(I6<=4,"Common (3-4)","Broad (5+)")))) -> Common (3-4) | L6: =IF(J6>=3,"Tier 1: Must in 3+ sources",IF(J6=2,"Tier 2: Must in 2 sources",IF(J6=1,"Tier 3: Must in 1 source",IF(COUNTIF(M6:R6,"S")>0,"Tier 4: Should only",IF(COUNTIF(M6:R6,"C")>0,"Tier 5: Could only",IF(I6>0,"Tier 6: stated, no priority","Aurigo-only")))))) -> Tier 2: Must in 2 sources | M6: M | N6: M | P6: E | S6: NH DOT ROWMS & Rail Requirements: Tab 7 Administrative – row 19 [Required / High]; Tab 6 Property Mgmt – row 20 [Required / High] Idaho ITD RFP Event 85 – ROWMS: §9 Management Reporting - General ['must' requirement (§9)] WSDOT RFI (2023): Perf. Requirements – Baseline System Capabilities [RFI – performance requirement list (no priority given)] | V6: Not evidenced | W6: No matching item found in the provided Aurigo documents (SOW, demo script, deck, library list). | X6: Filtering by region/district appears in NH (Admin tab and Property Mgmt reporting) and Idaho (dashboard district filter). | Z6: R02 | AA6: Project & parcel core | AB6: 16 | AC6: ROW-001
A7: ROW-004 | B7: Land Acquisition & Relocation | C7: Project & Parcel Setup | D7: Project record | E7: Project funding & estimate capture | F7: Record funding source and amount, design estimate and current estimate, and construction dates (letting, plan turn-in, projected construction start/completion) on the ROW project. | G7: Functional | H7: =IF(COUNTIF(M7:R7,"M")>0,"Must Have",IF(COUNTIF(M7:R7,"S")>0,"Should Have",IF(COUNTIF(M7:R7,"C")>0,"Could Have",IF(COUNTA(M7:R7)>0,"Stated – no priority","Aurigo-only (no RFP source)")))) -> Aurigo-only (no RFP source) | I7: =COUNTA(M7:R7) -> 0 | J7: =COUNTIF(M7:R7,"M") -> 0 | K7: =IF(I7=0,"Aurigo-only",IF(I7=1,"Single source",IF(I7=2,"Two sources",IF(I7<=4,"Common (3-4)","Broad (5+)")))) -> Aurigo-only | L7: =IF(J7>=3,"Tier 1: Must in 3+ sources",IF(J7=2,"Tier 2: Must in 2 sources",IF(J7=1,"Tier 3: Must in 1 source",IF(COUNTIF(M7:R7,"S")>0,"Tier 4: Should only",IF(COUNTIF(M7:R7,"C")>0,"Tier 5: Could only",IF(I7>0,"Tier 6: stated, no priority","Aurigo-only")))))) -> Aurigo-only | V7: Platform / demo only | W7: Demo script: ROW Project Details form (Funding Information, Design/Current Estimate, Construction Details) | X7: Aurigo-only: seen in the demo script, not requested in any provided RFP/RFI as a stand-alone item. | Z7: R04 | AA7: Project funding, parcel depth, acquisition plan & map viewer | AB7: 34 | AC7: ROW-001
A8: ROW-005 | B8: Land Acquisition & Relocation | C8: Project & Parcel Setup | D8: Parcel record | E8: Parcel record and parcel-level case tracking | F8: Manage each parcel as its own record (parcel number, legal description, address, area, type of property, tenant, status) and track the acquisition case at parcel level through its milestones. NH adds that data entered once should cascade to relocation needs. | G8: Functional | H8: =IF(COUNTIF(M8:R8,"M")>0,"Must Have",IF(COUNTIF(M8:R8,"S")>0,"Should Have",IF(COUNTIF(M8:R8,"C")>0,"Could Have",IF(COUNTA(M8:R8)>0,"Stated – no priority","Aurigo-only (no RFP source)")))) -> Must Have | I8: =COUNTA(M8:R8) -> 4 | J8: =COUNTIF(M8:R8,"M") -> 3 | K8: =IF(I8=0,"Aurigo-only",IF(I8=1,"Single source",IF(I8=2,"Two sources",IF(I8<=4,"Common (3-4)","Broad (5+)")))) -> Common (3-4) | L8: =IF(J8>=3,"Tier 1: Must in 3+ sources",IF(J8=2,"Tier 2: Must in 2 sources",IF(J8=1,"Tier 3: Must in 1 source",IF(COUNTIF(M8:R8,"S")>0,"Tier 4: Should only",IF(COUNTIF(M8:R8,"C")>0,"Tier 5: Could only",IF(I8>0,"Tier 6: stated, no priority","Aurigo-only")))))) -> Tier 1: Must in 3+ sources | M8: M | N8: M | P8: E | Q8: M | S8: NH DOT ROWMS & Rail Requirements: Tab 2 ROW Agent – row 4 [Required / High]; Tab 6 Property Mgmt – row 3 [Required / High] Idaho ITD RFP Event 85 – ROWMS: §9 Project Information Requirements ['must' requirement (§9)] WSDOT RFI (2023): Perf. Requirements – Property Acquisition & Relocation Services [RFI – performance requirement list (no priority given)] Austin Transit Partnership RFQ (2025): Scope – IV. Data Requirements [RFQ – requirement listed in scope] | V8: Covered (SOW) | W8: Pro SOW: 'Parcel', 'Parcel Location', 'Design Details'; Demo: Parcel Details form (status auto-updates from child forms) | Z8: R02 | AA8: Project & parcel core | AB8: 15 | AC8: ROW-001
A9: ROW-006 | B9: Land Acquisition & Relocation | C9: Project & Parcel Setup | D9: Parcel record | E9: Parcel grouping under projects / corridors with roll-up | F9: Group parcels under projects or corridors and roll their data up for reporting. | G9: Functional | H9: =IF(COUNTIF(M9:R9,"M")>0,"Must Have",IF(COUNTIF(M9:R9,"S")>0,"Should Have",IF(COUNTIF(M9:R9,"C")>0,"Could Have",IF(COUNTA(M9:R9)>0,"Stated – no priority","Aurigo-only (no RFP source)")))) -> Must Have | I9: =COUNTA(M9:R9) -> 1 | J9: =COUNTIF(M9:R9,"M") -> 1 | K9: =IF(I9=0,"Aurigo-only",IF(I9=1,"Single source",IF(I9=2,"Two sources",IF(I9<=4,"Common (3-4)","Broad (5+)")))) -> Single source | L9: =IF(J9>=3,"Tier 1: Must in 3+ sources",IF(J9=2,"Tier 2: Must in 2 sources",IF(J9=1,"Tier 3: Must in 1 source",IF(COUNTIF(M9:R9,"S")>0,"Tier 4: Should only",IF(COUNTIF(M9:R9,"C")>0,"Tier 5: Could only",IF(I9>0,"Tier 6: stated, no priority","Aurigo-only")))))) -> Tier 3: Must in 1 source | M9: M | S9: NH DOT ROWMS & Rail Requirements: Tab 2 ROW Agent – row 6 [Required / High] | V9: Partial | W9: Demo: parcels sit under the ROW Project navigation tree; corridor grouping not evidenced | Z9: R04 | AA9: Project funding, parcel depth, acquisition plan & map viewer | AB9: 39 | AC9: ROW-005
A10: ROW-007 | B10: Land Acquisition & Relocation | C10: Project & Parcel Setup | D10: Parcel record | E10: Combine / split parcels and remnant (uneconomic remainder) creation | F10: Combine or split parcel records; flag a parcel or part of one as a potential uneconomic remnant/remainder and assign it a new parcel number and ID. NH also asks to transfer post-construction remnants and classify them (e.g., surplus). | G10: Functional | H10: =IF(COUNTIF(M10:R10,"M")>0,"Must Have",IF(COUNTIF(M10:R10,"S")>0,"Should Have",IF(COUNTIF(M10:R10,"C")>0,"Could Have",IF(COUNTA(M10:R10)>0,"Stated – no priority","Aurigo-only (no RFP source)")))) -> Must Have | I10: =COUNTA(M10:R10) -> 2 | J10: =COUNTIF(M10:R10,"M") -> 1 | K10: =IF(I10=0,"Aurigo-only",IF(I10=1,"Single source",IF(I10=2,"Two sources",IF(I10<=4,"Common (3-4)","Broad (5+)")))) -> Two sources | L10: =IF(J10>=3,"Tier 1: Must in 3+ sources",IF(J10=2,"Tier 2: Must in 2 sources",IF(J10=1,"Tier 3: Must in 1 source",IF(COUNTIF(M10:R10,"S")>0,"Tier 4: Should only",IF(COUNTIF(M10:R10,"C")>0,"Tier 5: Could only",IF(I10>0,"Tier 6: stated, no priority","Aurigo-only")))))) -> Tier 3: Must in 1 source | M10: S | N10: M | S10: NH DOT ROWMS & Rail Requirements: Tab 6 Property Mgmt – row 7 [Desired / Medium] Idaho ITD RFP Event 85 – ROWMS: §9 Appraisal Requirements ['must' requirement (§9)] | V10: Covered (SOW) | W10: Pro SOW: 'Combine/Split Parcels' (ROW-level core process) | Z10: R04 | AA10: Project funding, parcel depth, acquisition plan & map viewer | AB10: 38 | AC10: ROW-005
A11: ROW-008 | B11: Land Acquisition & Relocation | C11: Project & Parcel Setup | D11: Parcel record | E11: Batch updates for multi-parcel projects | F11: Update many parcels at once (multi-parcel projects or corridor-wide additions) and support batch data entry. | G11: Functional | H11: =IF(COUNTIF(M11:R11,"M")>0,"Must Have",IF(COUNTIF(M11:R11,"S")>0,"Should Have",IF(COUNTIF(M11:R11,"C")>0,"Could Have",IF(COUNTA(M11:R11)>0,"Stated – no priority","Aurigo-only (no RFP source)")))) -> Must Have | I11: =COUNTA(M11:R11) -> 1 | J11: =COUNTIF(M11:R11,"M") -> 1 | K11: =IF(I11=0,"Aurigo-only",IF(I11=1,"Single source",IF(I11=2,"Two sources",IF(I11<=4,"Common (3-4)","Broad (5+)")))) -> Single source | L11: =IF(J11>=3,"Tier 1: Must in 3+ sources",IF(J11=2,"Tier 2: Must in 2 sources",IF(J11=1,"Tier 3: Must in 1 source",IF(COUNTIF(M11:R11,"S")>0,"Tier 4: Should only",IF(COUNTIF(M11:R11,"C")>0,"Tier 5: Could only",IF(I11>0,"Tier 6: stated, no priority","Aurigo-only")))))) -> Tier 3: Must in 1 source | M11: M | S11: NH DOT ROWMS & Rail Requirements: Tab 6 Property Mgmt – row 6 [Required / High]; Tab 7 Administrative – row 29 [Required / High] | V11: Not evidenced | W11: No matching item found in the provided Aurigo documents (SOW, demo script, deck, library list). | Z11: R04 | AA11: Project funding, parcel depth, acquisition plan & map viewer | AB11: 40 | AC11: ROW-005
A12: ROW-009 | B12: Land Acquisition & Relocation | C12: Project & Parcel Setup | D12: Parcel record | E12: Parcel synopsis / summary view and print | F12: Display or print a one-page summary of a parcel (location, owners, contacts, leases, tenants, title information). | G12: Functional | H12: =IF(COUNTIF(M12:R12,"M")>0,"Must Have",IF(COUNTIF(M12:R12,"S")>0,"Should Have",IF(COUNTIF(M12:R12,"C")>0,"Could Have",IF(COUNTA(M12:R12)>0,"Stated – no priority","Aurigo-only (no RFP source)")))) -> Must Have | I12: =COUNTA(M12:R12) -> 1 | J12: =COUNTIF(M12:R12,"M") -> 1 | K12: =IF(I12=0,"Aurigo-only",IF(I12=1,"Single source",IF(I12=2,"Two sources",IF(I12<=4,"Common (3-4)","Broad (5+)")))) -> Single source | L12: =IF(J12>=3,"Tier 1: Must in 3+ sources",IF(J12=2,"Tier 2: Must in 2 sources",IF(J12=1,"Tier 3: Must in 1 source",IF(COUNTIF(M12:R12,"S")>0,"Tier 4: Should only",IF(COUNTIF(M12:R12,"C")>0,"Tier 5: Could only",IF(I12>0,"Tier 6: stated, no priority","Aurigo-only")))))) -> Tier 3: Must in 1 source | N12: M | S12: Idaho ITD RFP Event 85 – ROWMS: §9 Negotiation and Acquisition Requirements ['must' requirement (§9)] | V12: Partial | W12: Demo: Parcel form shows Grantee, Appraisal, Agreement and Easement summaries | Z12: R04 | AA12: Project funding, parcel depth, acquisition plan & map viewer | AB12: 41 | AC12: ROW-005, ROW-014
A13: ROW-010 | B13: Land Acquisition & Relocation | C13: Project & Parcel Setup | D13: Parcel record | E13: Parcel milestone tracking with dates | F13: Track acquisition milestones per parcel with scheduled/completed dates and status (e.g., title verification, offer delivery, negotiation, acceptance, closing). | G13: Functional | H13: =IF(COUNTIF(M13:R13,"M")>0,"Must Have",IF(COUNTIF(M13:R13,"S")>0,"Should Have",IF(COUNTIF(M13:R13,"C")>0,"Could Have",IF(COUNTA(M13:R13)>0,"Stated – no priority","Aurigo-only (no RFP source)")))) -> Must Have | I13: =COUNTA(M13:R13) -> 2 | J13: =COUNTIF(M13:R13,"M") -> 2 | K13: =IF(I13=0,"Aurigo-only",IF(I13=1,"Single source",IF(I13=2,"Two sources",IF(I13<=4,"Common (3-4)","Broad (5+)")))) -> Two sources | L13: =IF(J13>=3,"Tier 1: Must in 3+ sources",IF(J13=2,"Tier 2: Must in 2 sources",IF(J13=1,"Tier 3: Must in 1 source",IF(COUNTIF(M13:R13,"S")>0,"Tier 4: Should only",IF(COUNTIF(M13:R13,"C")>0,"Tier 5: Could only",IF(I13>0,"Tier 6: stated, no priority","Aurigo-only")))))) -> Tier 2: Must in 2 sources | M13: M | Q13: M | S13: NH DOT ROWMS & Rail Requirements: Tab 2 ROW Agent – row 13 [Required / High] Austin Transit Partnership RFQ (2025): Scope – A. Data Management [RFQ – requirement listed in scope] | V13: Covered (SOW) | W13: Demo: Parcel Milestones grid and Agreement Milestones grid | Z13: R02 | AA13: Project & parcel core | AB13: 18 | AC13: ROW-005
A14: ROW-011 | B14: Land Acquisition & Relocation | C14: Project & Parcel Setup | D14: Parcel record | E14: Configurable parcel attributes | F14: Attach typed attributes with status and comments to a parcel, chosen from an admin-managed library. | G14: Functional | H14: =IF(COUNTIF(M14:R14,"M")>0,"Must Have",IF(COUNTIF(M14:R14,"S")>0,"Should Have",IF(COUNTIF(M14:R14,"C")>0,"Could Have",IF(COUNTA(M14:R14)>0,"Stated – no priority","Aurigo-only (no RFP source)")))) -> Aurigo-only (no RFP source) | I14: =COUNTA(M14:R14) -> 0 | J14: =COUNTIF(M14:R14,"M") -> 0 | K14: =IF(I14=0,"Aurigo-only",IF(I14=1,"Single source",IF(I14=2,"Two sources",IF(I14<=4,"Common (3-4)","Broad (5+)")))) -> Aurigo-only | L14: =IF(J14>=3,"Tier 1: Must in 3+ sources",IF(J14=2,"Tier 2: Must in 2 sources",IF(J14=1,"Tier 3: Must in 1 source",IF(COUNTIF(M14:R14,"S")>0,"Tier 4: Should only",IF(COUNTIF(M14:R14,"C")>0,"Tier 5: Could only",IF(I14>0,"Tier 6: stated, no priority","Aurigo-only")))))) -> Aurigo-only | V14: Covered (SOW) | W14: Demo: Parcel Attributes grid; Pro SOW libraries 'Attribute Type', 'Attribute Status' | X14: Aurigo-only. | Z14: R02 | AA14: Project & parcel core | AB14: 19 | AC14: ROW-005
A15: ROW-012 | B15: Land Acquisition & Relocation | C15: Project & Parcel Setup | D15: Cost & budget | E15: Project / parcel cost estimating with version history | F15: Enter and track cost estimates by project/parcel across cost types (land by use, site improvements, relocation, indirect costs such as appraisal, negotiation, closing, title insurance). Changing an estimate must keep the original and show prior versions. ATX also lists estimated vs. actual costs (property, closing, condemnation). | G15: Functional | H15: =IF(COUNTIF(M15:R15,"M")>0,"Must Have",IF(COUNTIF(M15:R15,"S")>0,"Should Have",IF(COUNTIF(M15:R15,"C")>0,"Could Have",IF(COUNTA(M15:R15)>0,"Stated – no priority","Aurigo-only (no RFP source)")))) -> Must Have | I15: =COUNTA(M15:R15) -> 2 | J15: =COUNTIF(M15:R15,"M") -> 2 | K15: =IF(I15=0,"Aurigo-only",IF(I15=1,"Single source",IF(I15=2,"Two sources",IF(I15<=4,"Common (3-4)","Broad (5+)")))) -> Two sources | L15: =IF(J15>=3,"Tier 1: Must in 3+ sources",IF(J15=2,"Tier 2: Must in 2 sources",IF(J15=1,"Tier 3: Must in 1 source",IF(COUNTIF(M15:R15,"S")>0,"Tier 4: Should only",IF(COUNTIF(M15:R15,"C")>0,"Tier 5: Could only",IF(I15>0,"Tier 6: stated, no priority","Aurigo-only")))))) -> Tier 2: Must in 2 sources | N15: M | Q15: M | S15: Idaho ITD RFP Event 85 – ROWMS: §9 Project Information Requirements ['must' requirement (§9)] ×2 Austin Transit Partnership RFQ (2025): Scope – A. Data Management [RFQ – requirement listed in scope] | V15: Partial | W15: Demo: Design/Current Estimate fields; SOW dashboards 'ROW - Project Cost Summary'. Estimate versioning not evidenced | Z15: R04 | AA15: Project funding, parcel depth, acquisition plan & map viewer | AB15: 35 | AC15: ROW-004
A16: ROW-013 | B16: Land Acquisition & Relocation | C16: Project & Parcel Setup | D16: Cost & budget | E16: ROW budget and audit support (annual budgets) | F16: Support fiscal planning for ROW acquisitions and utility costs, including preparing annual budgets and adjustments. | G16: Functional | H16: =IF(COUNTIF(M16:R16,"M")>0,"Must Have",IF(COUNTIF(M16:R16,"S")>0,"Should Have",IF(COUNTIF(M16:R16,"C")>0,"Could Have",IF(COUNTA(M16:R16)>0,"Stated – no priority","Aurigo-only (no RFP source)")))) -> Must Have | I16: =COUNTA(M16:R16) -> 1 | J16: =COUNTIF(M16:R16,"M") -> 1 | K16: =IF(I16=0,"Aurigo-only",IF(I16=1,"Single source",IF(I16=2,"Two sources",IF(I16<=4,"Common (3-4)","Broad (5+)")))) -> Single source | L16: =IF(J16>=3,"Tier 1: Must in 3+ sources",IF(J16=2,"Tier 2: Must in 2 sources",IF(J16=1,"Tier 3: Must in 1 source",IF(COUNTIF(M16:R16,"S")>0,"Tier 4: Should only",IF(COUNTIF(M16:R16,"C")>0,"Tier 5: Could only",IF(I16>0,"Tier 6: stated, no priority","Aurigo-only")))))) -> Tier 3: Must in 1 source | O16: M | S16: NMDOT RFP 06-0100: App. A §1 Introduction [SOW scope item / RFP purpose] | V16: Not evidenced | W16: No matching item found in the provided Aurigo documents (SOW, demo script, deck, library list). | X16: Only a one-line description in NM Appendix A; no detail on required functions. | Z16: R04 | AA16: Project funding, parcel depth, acquisition plan & map viewer | AB16: 36 | AC16: ROW-004
A17: ROW-014 | B17: Land Acquisition & Relocation | C17: Ownership & Stakeholders | D17: Owners | E17: Owner and ownership-interest management (multiple interests per parcel) | F17: Record owners and every interest in a parcel (fee, easement, tenant, lender, trustee, life estate, owner representative, etc.) with names, vesting-deed legal name, addresses and phone/email. | G17: Functional | H17: =IF(COUNTIF(M17:R17,"M")>0,"Must Have",IF(COUNTIF(M17:R17,"S")>0,"Should Have",IF(COUNTIF(M17:R17,"C")>0,"Could Have",IF(COUNTA(M17:R17)>0,"Stated – no priority","Aurigo-only (no RFP source)")))) -> Must Have | I17: =COUNTA(M17:R17) -> 4 | J17: =COUNTIF(M17:R17,"M") -> 3 | K17: =IF(I17=0,"Aurigo-only",IF(I17=1,"Single source",IF(I17=2,"Two sources",IF(I17<=4,"Common (3-4)","Broad (5+)")))) -> Common (3-4) | L17: =IF(J17>=3,"Tier 1: Must in 3+ sources",IF(J17=2,"Tier 2: Must in 2 sources",IF(J17=1,"Tier 3: Must in 1 source",IF(COUNTIF(M17:R17,"S")>0,"Tier 4: Should only",IF(COUNTIF(M17:R17,"C")>0,"Tier 5: Could only",IF(I17>0,"Tier 6: stated, no priority","Aurigo-only")))))) -> Tier 1: Must in 3+ sources | M17: M | N17: M | P17: E | Q17: M | S17: NH DOT ROWMS & Rail Requirements: Tab 2 ROW Agent – row 5 [Required / High] Idaho ITD RFP Event 85 – ROWMS: §9 Project Information Requirements ['must' requirement (§9)] ×2 WSDOT RFI (2023): Perf. Requirements – Property Acquisition & Relocation Services [RFI – performance requirement list (no priority given)] Austin Transit Partnership RFQ (2025): Scope – IV. Data Requirements [RFQ – requirement listed in scope] | V17: Covered (SOW) | W17: Pro SOW: 'Ownership Interest'; Demo: Ownership Interests form (owner type, addresses, contacts, representatives) | Z17: R03 | AA17: Owners, stakeholders & parcel team | AB17: 25 | AC17: ROW-005
A18: ROW-015 | B18: Land Acquisition & Relocation | C18: Ownership & Stakeholders | D18: Owners | E18: Multiple contacts per parcel (attorneys, banks, designees) | F18: Manage several contacts per parcel, such as owners, attorneys, banks and owner designees. | G18: Functional | H18: =IF(COUNTIF(M18:R18,"M")>0,"Must Have",IF(COUNTIF(M18:R18,"S")>0,"Should Have",IF(COUNTIF(M18:R18,"C")>0,"Could Have",IF(COUNTA(M18:R18)>0,"Stated – no priority","Aurigo-only (no RFP source)")))) -> Must Have | I18: =COUNTA(M18:R18) -> 1 | J18: =COUNTIF(M18:R18,"M") -> 1 | K18: =IF(I18=0,"Aurigo-only",IF(I18=1,"Single source",IF(I18=2,"Two sources",IF(I18<=4,"Common (3-4)","Broad (5+)")))) -> Single source | L18: =IF(J18>=3,"Tier 1: Must in 3+ sources",IF(J18=2,"Tier 2: Must in 2 sources",IF(J18=1,"Tier 3: Must in 1 source",IF(COUNTIF(M18:R18,"S")>0,"Tier 4: Should only",IF(COUNTIF(M18:R18,"C")>0,"Tier 5: Could only",IF(I18>0,"Tier 6: stated, no priority","Aurigo-only")))))) -> Tier 3: Must in 1 source | M18: M | S18: NH DOT ROWMS & Rail Requirements: Tab 2 ROW Agent – row 40 [Required / High] | V18: Covered (SOW) | W18: Demo: 'Representatives and Associates' grid on Ownership form | Z18: R03 | AA18: Owners, stakeholders & parcel team | AB18: 27 | AC18: ROW-014
A19: ROW-016 | B19: Land Acquisition & Relocation | C19: Ownership & Stakeholders | D19: Owners | E19: Tenant / occupant information | F19: Store tenant name and contacts, insurance, evidence of a lease and lease details for parcels. | G19: Functional | H19: =IF(COUNTIF(M19:R19,"M")>0,"Must Have",IF(COUNTIF(M19:R19,"S")>0,"Should Have",IF(COUNTIF(M19:R19,"C")>0,"Could Have",IF(COUNTA(M19:R19)>0,"Stated – no priority","Aurigo-only (no RFP source)")))) -> Must Have | I19: =COUNTA(M19:R19) -> 2 | J19: =COUNTIF(M19:R19,"M") -> 2 | K19: =IF(I19=0,"Aurigo-only",IF(I19=1,"Single source",IF(I19=2,"Two sources",IF(I19<=4,"Common (3-4)","Broad (5+)")))) -> Two sources | L19: =IF(J19>=3,"Tier 1: Must in 3+ sources",IF(J19=2,"Tier 2: Must in 2 sources",IF(J19=1,"Tier 3: Must in 1 source",IF(COUNTIF(M19:R19,"S")>0,"Tier 4: Should only",IF(COUNTIF(M19:R19,"C")>0,"Tier 5: Could only",IF(I19>0,"Tier 6: stated, no priority","Aurigo-only")))))) -> Tier 2: Must in 2 sources | N19: M | Q19: M | S19: Idaho ITD RFP Event 85 – ROWMS: §9 Project Information Requirements ['must' requirement (§9)] Austin Transit Partnership RFQ (2025): Scope – IV. Data Requirements [RFQ – requirement listed in scope] | V19: Partial | W19: Ownership form captures owners/representatives; tenant lease details not evidenced | Z19: R03 | AA19: Owners, stakeholders & parcel team | AB19: 26 | AC19: ROW-014
A20: ROW-017 | B20: Land Acquisition & Relocation | C20: Ownership & Stakeholders | D20: Owners | E20: Abutters / interested-parties list | F20: Build a comprehensive list of abutters and all parties of interest for a parcel; the same data feeds hearing notices. | G20: Functional | H20: =IF(COUNTIF(M20:R20,"M")>0,"Must Have",IF(COUNTIF(M20:R20,"S")>0,"Should Have",IF(COUNTIF(M20:R20,"C")>0,"Could Have",IF(COUNTA(M20:R20)>0,"Stated – no priority","Aurigo-only (no RFP source)")))) -> Must Have | I20: =COUNTA(M20:R20) -> 1 | J20: =COUNTIF(M20:R20,"M") -> 1 | K20: =IF(I20=0,"Aurigo-only",IF(I20=1,"Single source",IF(I20=2,"Two sources",IF(I20<=4,"Common (3-4)","Broad (5+)")))) -> Single source | L20: =IF(J20>=3,"Tier 1: Must in 3+ sources",IF(J20=2,"Tier 2: Must in 2 sources",IF(J20=1,"Tier 3: Must in 1 source",IF(COUNTIF(M20:R20,"S")>0,"Tier 4: Should only",IF(COUNTIF(M20:R20,"C")>0,"Tier 5: Could only",IF(I20>0,"Tier 6: stated, no priority","Aurigo-only")))))) -> Tier 3: Must in 1 source | M20: M | S20: NH DOT ROWMS & Rail Requirements: Tab 4 Land Titles – row 10 [Required / High]; Tab 7 Administrative – row 2 [Required / High] | V20: Not evidenced | W20: No matching item found in the provided Aurigo documents (SOW, demo script, deck, library list). | Z20: R03 | AA20: Owners, stakeholders & parcel team | AB20: 28 | AC20: ROW-014
A21: ROW-018 | B21: Land Acquisition & Relocation | C21: Ownership & Stakeholders | D21: Owners | E21: Tax identification capture (W-9 / 1099) for payees | F21: Hold payee tax details (1099, W-9) on the owner record and securely collect information needed for IRS reporting. | G21: Functional | H21: =IF(COUNTIF(M21:R21,"M")>0,"Must Have",IF(COUNTIF(M21:R21,"S")>0,"Should Have",IF(COUNTIF(M21:R21,"C")>0,"Could Have",IF(COUNTA(M21:R21)>0,"Stated – no priority","Aurigo-only (no RFP source)")))) -> Must Have | I21: =COUNTA(M21:R21) -> 1 | J21: =COUNTIF(M21:R21,"M") -> 1 | K21: =IF(I21=0,"Aurigo-only",IF(I21=1,"Single source",IF(I21=2,"Two sources",IF(I21<=4,"Common (3-4)","Broad (5+)")))) -> Single source | L21: =IF(J21>=3,"Tier 1: Must in 3+ sources",IF(J21=2,"Tier 2: Must in 2 sources",IF(J21=1,"Tier 3: Must in 1 source",IF(COUNTIF(M21:R21,"S")>0,"Tier 4: Should only",IF(COUNTIF(M21:R21,"C")>0,"Tier 5: Could only",IF(I21>0,"Tier 6: stated, no priority","Aurigo-only")))))) -> Tier 3: Must in 1 source | M21: M | S21: NH DOT ROWMS & Rail Requirements: Tab 7 Administrative – row 6 [Required / High] | T21: IRS 1099 / W-9 | V21: Covered (SOW) | W21: Demo: Ownership form > Tax Information (1099, W-9) | Z21: R03 | AA21: Owners, stakeholders & parcel team | AB21: 29 | AC21: ROW-014
A22: ROW-019 | B22: Land Acquisition & Relocation | C22: Ownership & Stakeholders | D22: Team | E22: Team / role assignment per parcel | F22: Assign people to roles on each parcel (appraisal coordinator, appraiser, reviewer, counsel, negotiator in-house or consultant, relocation agent, project lead, FHWA, etc.). | G22: Functional | H22: =IF(COUNTIF(M22:R22,"M")>0,"Must Have",IF(COUNTIF(M22:R22,"S")>0,"Should Have",IF(COUNTIF(M22:R22,"C")>0,"Could Have",IF(COUNTA(M22:R22)>0,"Stated – no priority","Aurigo-only (no RFP source)")))) -> Must Have | I22: =COUNTA(M22:R22) -> 2 | J22: =COUNTIF(M22:R22,"M") -> 2 | K22: =IF(I22=0,"Aurigo-only",IF(I22=1,"Single source",IF(I22=2,"Two sources",IF(I22<=4,"Common (3-4)","Broad (5+)")))) -> Two sources | L22: =IF(J22>=3,"Tier 1: Must in 3+ sources",IF(J22=2,"Tier 2: Must in 2 sources",IF(J22=1,"Tier 3: Must in 1 source",IF(COUNTIF(M22:R22,"S")>0,"Tier 4: Should only",IF(COUNTIF(M22:R22,"C")>0,"Tier 5: Could only",IF(I22>0,"Tier 6: stated, no priority","Aurigo-only")))))) -> Tier 2: Must in 2 sources | M22: M | N22: M | S22: NH DOT ROWMS & Rail Requirements: Tab 2 ROW Agent – row 4 [Required / High] Idaho ITD RFP Event 85 – ROWMS: §9 Project Information Requirements ['must' requirement (§9)] | V22: Covered (SOW) | W22: Demo: Agent Details grid; SOW library 'Agent Type' | Z22: R03 | AA22: Owners, stakeholders & parcel team | AB22: 31 | AC22: ROW-014, ROW-212
A23: ROW-020 | B23: Land Acquisition & Relocation | C23: Ownership & Stakeholders | D23: Communication | E23: Communication / negotiation diary log | F23: Log calls, meetings, mailings, emails and contact attempts per parcel (who, when, how, what was promised or answered); NH asks that negotiation conversations be documented automatically; a printable summary of diary entries per parcel is also requested. | G23: Functional | H23: =IF(COUNTIF(M23:R23,"M")>0,"Must Have",IF(COUNTIF(M23:R23,"S")>0,"Should Have",IF(COUNTIF(M23:R23,"C")>0,"Could Have",IF(COUNTA(M23:R23)>0,"Stated – no priority","Aurigo-only (no RFP source)")))) -> Must Have | I23: =COUNTA(M23:R23) -> 4 | J23: =COUNTIF(M23:R23,"M") -> 4 | K23: =IF(I23=0,"Aurigo-only",IF(I23=1,"Single source",IF(I23=2,"Two sources",IF(I23<=4,"Common (3-4)","Broad (5+)")))) -> Common (3-4) | L23: =IF(J23>=3,"Tier 1: Must in 3+ sources",IF(J23=2,"Tier 2: Must in 2 sources",IF(J23=1,"Tier 3: Must in 1 source",IF(COUNTIF(M23:R23,"S")>0,"Tier 4: Should only",IF(COUNTIF(M23:R23,"C")>0,"Tier 5: Could only",IF(I23>0,"Tier 6: stated, no priority","Aurigo-only")))))) -> Tier 1: Must in 3+ sources | M23: M | N23: M | O23: M | Q23: M | S23: NH DOT ROWMS & Rail Requirements: Tab 2 ROW Agent – row 19 [Required / High]; Tab 2 ROW Agent – row 41 [Required / High]; Tab 9 Reports – row 20 [Required / High] Idaho ITD RFP Event 85 – ROWMS: §9 Negotiation and Acquisition Requirements ['must' requirement (§9)] NMDOT RFP 06-0100: App. A §1 Introduction [SOW scope item / RFP purpose] Austin Transit Partnership RFQ (2025): Scope – A. Data Management [RFQ – requirement listed in scope] | V23: Covered (SOW) | W23: Original SOW: 'Agent Log' (configurable process); Demo: Agent Notes / Parcel Notes | X23: 'AUTO document' in NH T2!R19 is not explained in the source; I read it as automatic logging of contact events but this is unconfirmed. | Z23: R03 | AA23: Owners, stakeholders & parcel team | AB23: 32 | AC23: ROW-014
A24: ROW-021 | B24: Land Acquisition & Relocation | C24: Ownership & Stakeholders | D24: Communication | E24: Parcel notes with permission-controlled create/delete | F24: Create and delete notes on a record according to permissions. | G24: Functional | H24: =IF(COUNTIF(M24:R24,"M")>0,"Must Have",IF(COUNTIF(M24:R24,"S")>0,"Should Have",IF(COUNTIF(M24:R24,"C")>0,"Could Have",IF(COUNTA(M24:R24)>0,"Stated – no priority","Aurigo-only (no RFP source)")))) -> Must Have | I24: =COUNTA(M24:R24) -> 1 | J24: =COUNTIF(M24:R24,"M") -> 1 | K24: =IF(I24=0,"Aurigo-only",IF(I24=1,"Single source",IF(I24=2,"Two sources",IF(I24<=4,"Common (3-4)","Broad (5+)")))) -> Single source | L24: =IF(J24>=3,"Tier 1: Must in 3+ sources",IF(J24=2,"Tier 2: Must in 2 sources",IF(J24=1,"Tier 3: Must in 1 source",IF(COUNTIF(M24:R24,"S")>0,"Tier 4: Should only",IF(COUNTIF(M24:R24,"C")>0,"Tier 5: Could only",IF(I24>0,"Tier 6: stated, no priority","Aurigo-only")))))) -> Tier 3: Must in 1 source | M24: M | S24: NH DOT ROWMS & Rail Requirements: Tab 9 Reports – row 9 [Required / High] | V24: Covered (SOW) | W24: Demo: Parcel Notes section (made by / made on / status) | Z24: R03 | AA24: Owners, stakeholders & parcel team | AB24: 33 | AC24: ROW-005, ROW-213
A25: ROW-022 | B25: Land Acquisition & Relocation | C25: Ownership & Stakeholders | D25: Demographics | E25: Owner / displacee demographic capture for civil-rights statistics | F25: Capture sex and ethnicity (minority / non-minority / female) of owners and displacees for statistical reporting. | G25: Functional | H25: =IF(COUNTIF(M25:R25,"M")>0,"Must Have",IF(COUNTIF(M25:R25,"S")>0,"Should Have",IF(COUNTIF(M25:R25,"C")>0,"Could Have",IF(COUNTA(M25:R25)>0,"Stated – no priority","Aurigo-only (no RFP source)")))) -> Must Have | I25: =COUNTA(M25:R25) -> 1 | J25: =COUNTIF(M25:R25,"M") -> 1 | K25: =IF(I25=0,"Aurigo-only",IF(I25=1,"Single source",IF(I25=2,"Two sources",IF(I25<=4,"Common (3-4)","Broad (5+)")))) -> Single source | L25: =IF(J25>=3,"Tier 1: Must in 3+ sources",IF(J25=2,"Tier 2: Must in 2 sources",IF(J25=1,"Tier 3: Must in 1 source",IF(COUNTIF(M25:R25,"S")>0,"Tier 4: Should only",IF(COUNTIF(M25:R25,"C")>0,"Tier 5: Could only",IF(I25>0,"Tier 6: stated, no priority","Aurigo-only")))))) -> Tier 3: Must in 1 source | N25: M | S25: Idaho ITD RFP Event 85 – ROWMS: §9 Negotiation and Acquisition Requirements ['must' requirement (§9)]; §9 Relocation Requirements ['must' requirement (§9)] | T25: Title VI (civil rights) reporting | V25: Not evidenced | W25: No matching item found in the provided Aurigo documents (SOW, demo script, deck, library list). | Z25: R03 | AA25: Owners, stakeholders & parcel team | AB25: 30 | AC25: ROW-014
A26: ROW-023 | B26: Land Acquisition & Relocation | C26: Title & Abstraction | D26: Title records | E26: Chain of title and historical ownership | F26: Manage chain of title and historical ownership records; identify landownership and existing encumbrances; record title information and title-report specifics on acquisitions, including liens and mortgages. | G26: Functional | H26: =IF(COUNTIF(M26:R26,"M")>0,"Must Have",IF(COUNTIF(M26:R26,"S")>0,"Should Have",IF(COUNTIF(M26:R26,"C")>0,"Could Have",IF(COUNTA(M26:R26)>0,"Stated – no priority","Aurigo-only (no RFP source)")))) -> Must Have | I26: =COUNTA(M26:R26) -> 4 | J26: =COUNTIF(M26:R26,"M") -> 3 | K26: =IF(I26=0,"Aurigo-only",IF(I26=1,"Single source",IF(I26=2,"Two sources",IF(I26<=4,"Common (3-4)","Broad (5+)")))) -> Common (3-4) | L26: =IF(J26>=3,"Tier 1: Must in 3+ sources",IF(J26=2,"Tier 2: Must in 2 sources",IF(J26=1,"Tier 3: Must in 1 source",IF(COUNTIF(M26:R26,"S")>0,"Tier 4: Should only",IF(COUNTIF(M26:R26,"C")>0,"Tier 5: Could only",IF(I26>0,"Tier 6: stated, no priority","Aurigo-only")))))) -> Tier 1: Must in 3+ sources | M26: M | O26: M | P26: E | Q26: M | S26: NH DOT ROWMS & Rail Requirements: Tab 4 Land Titles – row 3 [Required / High] NMDOT RFP 06-0100: App. A §1 Introduction [SOW scope item / RFP purpose] WSDOT RFI (2023): Perf. Requirements – Property Acquisition & Relocation Services [RFI – performance requirement list (no priority given)] Austin Transit Partnership RFQ (2025): Scope – IV. Data Requirements [RFQ – requirement listed in scope] | V26: Covered (SOW) | W26: Pro SOW: 'Title Search & Due Diligence' (core process) | Z26: R07 | AA26: Title & abstraction | AB26: 70 | AC26: ROW-005, ROW-014, ROW-157
A27: ROW-024 | B27: Land Acquisition & Relocation | C27: Title & Abstraction | D27: Title records | E27: Title defect / encumbrance tracking with alerts | F27: Track and flag/alert on title defects, encumbrances, easements and unresolved issues. | G27: Functional | H27: =IF(COUNTIF(M27:R27,"M")>0,"Must Have",IF(COUNTIF(M27:R27,"S")>0,"Should Have",IF(COUNTIF(M27:R27,"C")>0,"Could Have",IF(COUNTA(M27:R27)>0,"Stated – no priority","Aurigo-only (no RFP source)")))) -> Must Have | I27: =COUNTA(M27:R27) -> 1 | J27: =COUNTIF(M27:R27,"M") -> 1 | K27: =IF(I27=0,"Aurigo-only",IF(I27=1,"Single source",IF(I27=2,"Two sources",IF(I27<=4,"Common (3-4)","Broad (5+)")))) -> Single source | L27: =IF(J27>=3,"Tier 1: Must in 3+ sources",IF(J27=2,"Tier 2: Must in 2 sources",IF(J27=1,"Tier 3: Must in 1 source",IF(COUNTIF(M27:R27,"S")>0,"Tier 4: Should only",IF(COUNTIF(M27:R27,"C")>0,"Tier 5: Could only",IF(I27>0,"Tier 6: stated, no priority","Aurigo-only")))))) -> Tier 3: Must in 1 source | M27: M | S27: NH DOT ROWMS & Rail Requirements: Tab 4 Land Titles – row 4 [Required / High] | V27: Not evidenced | W27: No matching item found in the provided Aurigo documents (SOW, demo script, deck, library list). | Z27: R07 | AA27: Title & abstraction | AB27: 71 | AC27: ROW-023
A28: ROW-025 | B28: Land Acquisition & Relocation | C28: Title & Abstraction | D28: Title records | E28: Title commitment details | F28: Store title commitment number and expiration date as parcel data. | G28: Functional | H28: =IF(COUNTIF(M28:R28,"M")>0,"Must Have",IF(COUNTIF(M28:R28,"S")>0,"Should Have",IF(COUNTIF(M28:R28,"C")>0,"Could Have",IF(COUNTA(M28:R28)>0,"Stated – no priority","Aurigo-only (no RFP source)")))) -> Must Have | I28: =COUNTA(M28:R28) -> 1 | J28: =COUNTIF(M28:R28,"M") -> 1 | K28: =IF(I28=0,"Aurigo-only",IF(I28=1,"Single source",IF(I28=2,"Two sources",IF(I28<=4,"Common (3-4)","Broad (5+)")))) -> Single source | L28: =IF(J28>=3,"Tier 1: Must in 3+ sources",IF(J28=2,"Tier 2: Must in 2 sources",IF(J28=1,"Tier 3: Must in 1 source",IF(COUNTIF(M28:R28,"S")>0,"Tier 4: Should only",IF(COUNTIF(M28:R28,"C")>0,"Tier 5: Could only",IF(I28>0,"Tier 6: stated, no priority","Aurigo-only")))))) -> Tier 3: Must in 1 source | N28: M | S28: Idaho ITD RFP Event 85 – ROWMS: §9 Project Information Requirements ['must' requirement (§9)] | V28: Not evidenced | W28: No matching item found in the provided Aurigo documents (SOW, demo script, deck, library list). | Z28: R07 | AA28: Title & abstraction | AB28: 72 | AC28: ROW-023
A29: ROW-026 | B29: Land Acquisition & Relocation | C29: Title & Abstraction | D29: Title records | E29: Link and search title documents (deeds, plats, surveys, title reports) | F29: Store and link scanned deeds, plats, surveys and title reports to parcels/tracts; search by owner name, map/lot number, deed reference or parcel ID, including by GIS. | G29: Functional | H29: =IF(COUNTIF(M29:R29,"M")>0,"Must Have",IF(COUNTIF(M29:R29,"S")>0,"Should Have",IF(COUNTIF(M29:R29,"C")>0,"Could Have",IF(COUNTA(M29:R29)>0,"Stated – no priority","Aurigo-only (no RFP source)")))) -> Must Have | I29: =COUNTA(M29:R29) -> 1 | J29: =COUNTIF(M29:R29,"M") -> 1 | K29: =IF(I29=0,"Aurigo-only",IF(I29=1,"Single source",IF(I29=2,"Two sources",IF(I29<=4,"Common (3-4)","Broad (5+)")))) -> Single source | L29: =IF(J29>=3,"Tier 1: Must in 3+ sources",IF(J29=2,"Tier 2: Must in 2 sources",IF(J29=1,"Tier 3: Must in 1 source",IF(COUNTIF(M29:R29,"S")>0,"Tier 4: Should only",IF(COUNTIF(M29:R29,"C")>0,"Tier 5: Could only",IF(I29>0,"Tier 6: stated, no priority","Aurigo-only")))))) -> Tier 3: Must in 1 source | M29: M | S29: NH DOT ROWMS & Rail Requirements: Tab 4 Land Titles – row 5 [Required / High]; Tab 4 Land Titles – row 12 [Required / High]; Tab 8 Rail & Transit – row 19 [Required / High]; Tab 8 Rail & Transit – row 20 [Required / High] | V29: Not evidenced | W29: No matching item found in the provided Aurigo documents (SOW, demo script, deck, library list). | Z29: R07 | AA29: Title & abstraction | AB29: 73 | AC29: ROW-023, ROW-158
A30: ROW-027 | B30: Land Acquisition & Relocation | C30: Title & Abstraction | D30: Title records | E30: Title versioning and update flags through project lifecycle | F30: Track versions of modified title research and flag titles that must be updated as a project moves (e.g., preliminary to final); accept update requests. | G30: Functional | H30: =IF(COUNTIF(M30:R30,"M")>0,"Must Have",IF(COUNTIF(M30:R30,"S")>0,"Should Have",IF(COUNTIF(M30:R30,"C")>0,"Could Have",IF(COUNTA(M30:R30)>0,"Stated – no priority","Aurigo-only (no RFP source)")))) -> Must Have | I30: =COUNTA(M30:R30) -> 1 | J30: =COUNTIF(M30:R30,"M") -> 1 | K30: =IF(I30=0,"Aurigo-only",IF(I30=1,"Single source",IF(I30=2,"Two sources",IF(I30<=4,"Common (3-4)","Broad (5+)")))) -> Single source | L30: =IF(J30>=3,"Tier 1: Must in 3+ sources",IF(J30=2,"Tier 2: Must in 2 sources",IF(J30=1,"Tier 3: Must in 1 source",IF(COUNTIF(M30:R30,"S")>0,"Tier 4: Should only",IF(COUNTIF(M30:R30,"C")>0,"Tier 5: Could only",IF(I30>0,"Tier 6: stated, no priority","Aurigo-only")))))) -> Tier 3: Must in 1 source | M30: M | S30: NH DOT ROWMS & Rail Requirements: Tab 4 Land Titles – row 18 [Required / High]; Tab 4 Land Titles – row 20 [Required / High] | V30: Not evidenced | W30: No matching item found in the provided Aurigo documents (SOW, demo script, deck, library list). | Z30: R07 | AA30: Title & abstraction | AB30: 74 | AC30: ROW-023, ROW-160
A31: ROW-028 | B31: Land Acquisition & Relocation | C31: Title & Abstraction | D31: Title records | E31: Confidential title information by role | F31: Restrict sensitive title information by role (example: only legal can see confidential opinions). | G31: Functional | H31: =IF(COUNTIF(M31:R31,"M")>0,"Must Have",IF(COUNTIF(M31:R31,"S")>0,"Should Have",IF(COUNTIF(M31:R31,"C")>0,"Could Have",IF(COUNTA(M31:R31)>0,"Stated – no priority","Aurigo-only (no RFP source)")))) -> Must Have | I31: =COUNTA(M31:R31) -> 1 | J31: =COUNTIF(M31:R31,"M") -> 1 | K31: =IF(I31=0,"Aurigo-only",IF(I31=1,"Single source",IF(I31=2,"Two sources",IF(I31<=4,"Common (3-4)","Broad (5+)")))) -> Single source | L31: =IF(J31>=3,"Tier 1: Must in 3+ sources",IF(J31=2,"Tier 2: Must in 2 sources",IF(J31=1,"Tier 3: Must in 1 source",IF(COUNTIF(M31:R31,"S")>0,"Tier 4: Should only",IF(COUNTIF(M31:R31,"C")>0,"Tier 5: Could only",IF(I31>0,"Tier 6: stated, no priority","Aurigo-only")))))) -> Tier 3: Must in 1 source | M31: M | S31: NH DOT ROWMS & Rail Requirements: Tab 4 Land Titles – row 21 [Required / High] | V31: Not evidenced | W31: No matching item found in the provided Aurigo documents (SOW, demo script, deck, library list). | Z31: R07 | AA31: Title & abstraction | AB31: 75 | AC31: ROW-023, ROW-213
A32: ROW-029 | B32: Land Acquisition & Relocation | C32: Title & Abstraction | D32: Title records | E32: Land-type classification and grouping | F32: Identify/group parcels by land type (private, condo, conservation, recreation, etc.). | G32: Functional | H32: =IF(COUNTIF(M32:R32,"M")>0,"Must Have",IF(COUNTIF(M32:R32,"S")>0,"Should Have",IF(COUNTIF(M32:R32,"C")>0,"Could Have",IF(COUNTA(M32:R32)>0,"Stated – no priority","Aurigo-only (no RFP source)")))) -> Must Have | I32: =COUNTA(M32:R32) -> 1 | J32: =COUNTIF(M32:R32,"M") -> 1 | K32: =IF(I32=0,"Aurigo-only",IF(I32=1,"Single source",IF(I32=2,"Two sources",IF(I32<=4,"Common (3-4)","Broad (5+)")))) -> Single source | L32: =IF(J32>=3,"Tier 1: Must in 3+ sources",IF(J32=2,"Tier 2: Must in 2 sources",IF(J32=1,"Tier 3: Must in 1 source",IF(COUNTIF(M32:R32,"S")>0,"Tier 4: Should only",IF(COUNTIF(M32:R32,"C")>0,"Tier 5: Could only",IF(I32>0,"Tier 6: stated, no priority","Aurigo-only")))))) -> Tier 3: Must in 1 source | M32: M | S32: NH DOT ROWMS & Rail Requirements: Tab 4 Land Titles – row 9 [Required / High] | V32: Not evidenced | W32: No matching item found in the provided Aurigo documents (SOW, demo script, deck, library list). | X32: NH T4!R9 ends with 'Lchip et al.'; 'Lchip' is not defined in the file and I do not know what it refers to. | Z32: R07 | AA32: Title & abstraction | AB32: 76 | AC32: ROW-023
A33: ROW-030 | B33: Land Acquisition & Relocation | C33: Title & Abstraction | D33: Plans & workload | E33: ROW plan request tracking and workload/delivery estimating | F33: Capture ROW plan requests, project progress, reporting dates and progress indicators; help estimate workload and delivery dates; report levels of plan requests completed and abstracts/title reports completed per project. | G33: Functional | H33: =IF(COUNTIF(M33:R33,"M")>0,"Must Have",IF(COUNTIF(M33:R33,"S")>0,"Should Have",IF(COUNTIF(M33:R33,"C")>0,"Could Have",IF(COUNTA(M33:R33)>0,"Stated – no priority","Aurigo-only (no RFP source)")))) -> Must Have | I33: =COUNTA(M33:R33) -> 1 | J33: =COUNTIF(M33:R33,"M") -> 1 | K33: =IF(I33=0,"Aurigo-only",IF(I33=1,"Single source",IF(I33=2,"Two sources",IF(I33<=4,"Common (3-4)","Broad (5+)")))) -> Single source | L33: =IF(J33>=3,"Tier 1: Must in 3+ sources",IF(J33=2,"Tier 2: Must in 2 sources",IF(J33=1,"Tier 3: Must in 1 source",IF(COUNTIF(M33:R33,"S")>0,"Tier 4: Should only",IF(COUNTIF(M33:R33,"C")>0,"Tier 5: Could only",IF(I33>0,"Tier 6: stated, no priority","Aurigo-only")))))) -> Tier 3: Must in 1 source | M33: M | S33: NH DOT ROWMS & Rail Requirements: Tab 4 Land Titles – row 6 [Required / High]; Tab 4 Land Titles – row 8 [Required / High]; Tab 9 Reports – row 5 [Required / High]; Tab 9 Reports – row 6 [Required / High] | V33: Not evidenced | W33: No matching item found in the provided Aurigo documents (SOW, demo script, deck, library list). | Z33: R07 | AA33: Title & abstraction | AB33: 66 | AC33: ROW-005, ROW-166
A34: ROW-031 | B34: Land Acquisition & Relocation | C34: Title & Abstraction | D34: Vendors | E34: External title-examiner contracts and vendor portal | F34: Manage contracts with external fee-title examiners; external contractors access and upload through an external-facing portal. | G34: Functional | H34: =IF(COUNTIF(M34:R34,"M")>0,"Must Have",IF(COUNTIF(M34:R34,"S")>0,"Should Have",IF(COUNTIF(M34:R34,"C")>0,"Could Have",IF(COUNTA(M34:R34)>0,"Stated – no priority","Aurigo-only (no RFP source)")))) -> Must Have | I34: =COUNTA(M34:R34) -> 1 | J34: =COUNTIF(M34:R34,"M") -> 1 | K34: =IF(I34=0,"Aurigo-only",IF(I34=1,"Single source",IF(I34=2,"Two sources",IF(I34<=4,"Common (3-4)","Broad (5+)")))) -> Single source | L34: =IF(J34>=3,"Tier 1: Must in 3+ sources",IF(J34=2,"Tier 2: Must in 2 sources",IF(J34=1,"Tier 3: Must in 1 source",IF(COUNTIF(M34:R34,"S")>0,"Tier 4: Should only",IF(COUNTIF(M34:R34,"C")>0,"Tier 5: Could only",IF(I34>0,"Tier 6: stated, no priority","Aurigo-only")))))) -> Tier 3: Must in 1 source | M34: M | S34: NH DOT ROWMS & Rail Requirements: Tab 4 Land Titles – row 7 [Required / High]; Tab 1 General – row 3 [Required / High] | V34: Not evidenced | W34: No matching item found in the provided Aurigo documents (SOW, demo script, deck, library list). | Z34: R32 | AA34: External portals, public access & records | AB34: 298 | AC34: ROW-023, ROW-173
